<?xml version="1.0" encoding="utf-8" ?>
<!-- =================================================================================== -->
<!-- |    This document was autogenerated by xacro from /home/hello/moveit_ws/src/ovis/ovis_description/urdf/ovis_standalone.xacro | -->
<!-- |    EDITING THIS FILE BY HAND IS NOT RECOMMENDED                                 | -->
<!-- =================================================================================== -->
<!-- OVIS 6DOF spherical wrist robotic arm -->
<robot name="ovis" xmlns:body="http://playerstage.sourceforge.net/gazebo/xmlschema/#body" xmlns:controller="http://playerstage.sourceforge.net/gazebo/xmlschema/#controller" xmlns:gazebo="http://playerstage.sourceforge.net/gazebo/xmlschema/#gz" xmlns:geom="http://playerstage.sourceforge.net/gazebo/xmlschema/#geom" xmlns:interface="http://playerstage.sourceforge.net/gazebo/xmlschema/#interface" xmlns:joint="http://playerstage.sourceforge.net/gazebo/xmlschema/#joint" xmlns:model="http://playerstage.sourceforge.net/gazebo/xmlschema/#model" xmlns:physics="http://playerstage.sourceforge.net/gazebo/xmlschema/#physics" xmlns:renderable="http://playerstage.sourceforge.net/gazebo/xmlschema/#renderable" xmlns:rendering="http://playerstage.sourceforge.net/gazebo/xmlschema/#rendering" xmlns:sensor="http://playerstage.sourceforge.net/gazebo/xmlschema/#sensor" xmlns:xi="http://www.w3.org/2001/XInclude">
    <gazebo reference="ovis_link_base">
        <material>Gazebo/Red</material>
    </gazebo>
    <gazebo reference="ovis_link_1">
        <material>Gazebo/Red</material>
    </gazebo>
    <gazebo reference="ovis_link_2">
        <material>Gazebo/Red</material>
    </gazebo>
    <gazebo reference="ovis_link_3">
        <material>Gazebo/Red</material>
    </gazebo>
    <gazebo reference="ovis_link_4">
        <material>Gazebo/Red</material>
    </gazebo>
    <gazebo reference="ovis_link_5">
        <material>Gazebo/Red</material>
    </gazebo>
    <gazebo reference="ovis_link_6">
        <material>Gazebo/Red</material>
    </gazebo>
    <gazebo reference="ovis_camera">
        <material>Gazebo/Green</material>
        <sensor name="pt_grey_chameleon" type="camera">
            <update_rate>30.0</update_rate>
            <camera name="head">
                <horizontal_fov>1.3962634</horizontal_fov>
                <image>
                    <width>1296</width>
                    <height>964</height>
                    <format>R8G8B8</format>
                </image>
                <clip>
                    <near>0.01</near>
                    <far>100</far>
                </clip>
            </camera>
            <plugin filename="libgazebo_ros_camera.so" name="camera_controller">
                <alwaysOn>true</alwaysOn>
                <updateRate>18</updateRate>
                <cameraName>ovis/pt_grey_chameleon</cameraName>
                <imageTopicName>image_raw</imageTopicName>
                <cameraInfoTopicName>camera_info</cameraInfoTopicName>
                <frameName>camera</frameName>
                <hackBaseline>0.07</hackBaseline>
                <distortionK1>0.0</distortionK1>
                <distortionK2>0.0</distortionK2>
                <distortionK3>0.0</distortionK3>
                <distortionT1>0.0</distortionT1>
                <distortionT2>0.0</distortionT2>
            </plugin>
        </sensor>
    </gazebo>
    <!-- camera link -->
    <link name="ovis_camera">
        
<inertial>
            <mass value=".1" />
            <origin rpy="0 0 0" xyz="0 0 0" />
            <inertia ixx="0" ixy="0.0" ixz="0.0" iyy="0" iyz="0.0" izz="0" />
        </inertial>

        <!-- <visual>
            <geometry>
                <box size=".01 .01 .01"/>
            </geometry>
        </visual> -->
    </link>
    <link name="ovis_root" />
    <!-- ros_control plugin -->
    <gazebo>
        <plugin filename="libgazebo_ros_control.so" name="gazebo_ros_control">
            <robotNamespace>ovis</robotNamespace>
            <robotSimType>gazebo_ros_control/DefaultRobotHWSim</robotSimType>
            <legacyModeNS>true</legacyModeNS>
        </plugin>
    </gazebo>
    <link name="ovis_link_base">
        <visual>
            <geometry>
                <mesh filename="package://ovis_description/meshes/visual/ovis_base.stl" />
            </geometry>
            <origin rpy="1.57079632679 0 0" xyz="0 0 0" />
        </visual>
        <collision>
            <geometry>
                <mesh filename="package://ovis_description/meshes/visual/ovis_base.stl" />
            </geometry>
            <origin rpy="1.57079632679 0 0" xyz="0 0 0" />
        </collision>
        
<inertial>
            <mass value="1.53" />
            <origin rpy="0 0 0" xyz="0 0 0.04385330" />
            <inertia ixx="0.00320907" ixy="2e-008" ixz="2e-008" iyy="0.00321098" iyz="-6e-007" izz="0.0056695" />
        </inertial>

    </link>
    <joint name="ovis_joint_base" type="fixed">
        <parent link="ovis_root" />
        <child link="ovis_link_base" />
        <axis xyz="0 0 0" />
        <limit effort="0" lower="0" upper="0" velocity="0" />
        <origin rpy="0 0 0" xyz="0 0 0" />
        <dynamics damping="0.0" friction="0.0" />
    </joint>
    <link name="ovis_link_1">
        <visual>
            <geometry>
                <mesh filename="package://ovis_description/meshes/visual/ovis_shoulder.stl" />
            </geometry>
            <origin rpy="1.57079632679 0 0" xyz="0 0 0" />
        </visual>
        <collision>
            <geometry>
                <mesh filename="package://ovis_description/meshes/visual/ovis_shoulder.stl" />
            </geometry>
            <origin rpy="1.57079632679 0 0" xyz="0 0 0" />
        </collision>
        
<inertial>
            <mass value="1.2" />
            <origin rpy="0 0 0" xyz="0 -0.0111 0.055" />
            <inertia ixx="0.00248772" ixy="-1.6e-007" ixz="2.2e-007" iyy="0.0027245" iyz="-0.00031134" izz="0.00126329" />
        </inertial>

    </link>
    <joint name="arm_joint_1" type="continuous">
        <parent link="ovis_link_base" />
        <child link="ovis_link_1" />
        <axis xyz="0 0 1" />
        <limit effort="40" lower="-12.5663706144" upper="12.5663706144" velocity="0.628318530718" />
        <origin rpy="0 0 0" xyz="0 0 0.051" />
        <dynamics damping="0.0" friction="0.0" />
    </joint>
    <transmission name="arm_joint_1_trans">
        <type>transmission_interface/SimpleTransmission</type>
        <joint name="arm_joint_1">
            <hardwareInterface>hardware_interface/PositionJointInterface</hardwareInterface>
        </joint>
        <actuator name="arm_joint_1_actuator">
            <hardwareInterface>hardware_interface/PositionJointInterface</hardwareInterface>
            <mechanicalReduction>160</mechanicalReduction>
        </actuator>
    </transmission>
    <!--For torque sensing in simulation-->
    <gazebo reference="arm_joint_1">
        <provideFeedback>true</provideFeedback>
    </gazebo>
    <gazebo>
        <plugin filename="libgazebo_ros_ft_sensor.so" name="ft_sensor">
            <updateRate>30.0</updateRate>
            <topicName>arm_joint_1_ft_sensor_topic</topicName>
            <jointName>arm_joint_1</jointName>
        </plugin>
    </gazebo>
    <link name="ovis_link_2">
        <visual>
            <geometry>
                <mesh filename="package://ovis_description/meshes/visual/ovis_upper_arm.stl" />
            </geometry>
            <origin rpy="0 0 0" xyz="0 0 0" />
        </visual>
        <collision>
            <geometry>
                <mesh filename="package://ovis_description/meshes/visual/ovis_upper_arm.stl" />
            </geometry>
            <origin rpy="0 0 0" xyz="0 0 0" />
        </collision>
        
<inertial>
            <mass value="1.3" />
            <origin rpy="0 0 0" xyz="0 0.17553971 -0.00935895" />
            <inertia ixx="0.03068681" ixy="1.76e-006" ixz="1e-007" iyy="0.00109408" iyz="0.00018345" izz="0.03103519" />
        </inertial>

    </link>
    <joint name="arm_joint_2" type="revolute">
        <parent link="ovis_link_1" />
        <child link="ovis_link_2" />
        <axis xyz="0 0 1" />
        <limit effort="80" lower="-1.57079632679" upper="1.57079632679" velocity="0.628318530718" />
        <origin rpy="1.57079632679 0 0" xyz="0 0 0.0889" />
        <dynamics damping="0.0" friction="0.0" />
    </joint>
    <transmission name="arm_joint_2_trans">
        <type>transmission_interface/SimpleTransmission</type>
        <joint name="arm_joint_2">
            <hardwareInterface>hardware_interface/PositionJointInterface</hardwareInterface>
        </joint>
        <actuator name="arm_joint_2_actuator">
            <hardwareInterface>hardware_interface/PositionJointInterface</hardwareInterface>
            <mechanicalReduction>160</mechanicalReduction>
        </actuator>
    </transmission>
    <!--For torque sensing in simulation-->
    <gazebo reference="arm_joint_2">
        <provideFeedback>true</provideFeedback>
    </gazebo>
    <gazebo>
        <plugin filename="libgazebo_ros_ft_sensor.so" name="ft_sensor">
            <updateRate>30.0</updateRate>
            <topicName>arm_joint_2_ft_sensor_topic</topicName>
            <jointName>arm_joint_2</jointName>
        </plugin>
    </gazebo>
    <link name="ovis_link_3">
        <visual>
            <geometry>
                <mesh filename="package://ovis_description/meshes/visual/ovis_elbow.stl" />
            </geometry>
            <origin rpy="0 0 0" xyz="0 0 0" />
        </visual>
        <collision>
            <geometry>
                <mesh filename="package://ovis_description/meshes/visual/ovis_elbow.stl" />
            </geometry>
            <origin rpy="0 0 0" xyz="0 0 0" />
        </collision>
        
<inertial>
            <mass value="0.592" />
            <origin rpy="0 0 0" xyz="0.03828435 0.01104986 0.00979839" />
            <inertia ixx="0.00049443" ixy="0.00033167" ixz="-0.00021435" iyy="0.00147579" iyz="-6.259e-005" izz="0.0016474" />
        </inertial>

    </link>
    <joint name="arm_joint_3" type="revolute">
        <parent link="ovis_link_2" />
        <child link="ovis_link_3" />
        <axis xyz="0 0 1" />
        <limit effort="40" lower="-1.57079632679" upper="1.57079632679" velocity="0.628318530718" />
        <origin rpy="0 0 1.57079632679" xyz="0 0.465 0" />
        <dynamics damping="0.0" friction="0.0" />
    </joint>
    <transmission name="arm_joint_3_trans">
        <type>transmission_interface/SimpleTransmission</type>
        <joint name="arm_joint_3">
            <hardwareInterface>hardware_interface/PositionJointInterface</hardwareInterface>
        </joint>
        <actuator name="arm_joint_3_actuator">
            <hardwareInterface>hardware_interface/PositionJointInterface</hardwareInterface>
            <mechanicalReduction>160</mechanicalReduction>
        </actuator>
    </transmission>
    <!--For torque sensing in simulation-->
    <gazebo reference="arm_joint_3">
        <provideFeedback>true</provideFeedback>
    </gazebo>
    <gazebo>
        <plugin filename="libgazebo_ros_ft_sensor.so" name="ft_sensor">
            <updateRate>30.0</updateRate>
            <topicName>arm_joint_3_ft_sensor_topic</topicName>
            <jointName>arm_joint_3</jointName>
        </plugin>
    </gazebo>
    <link name="ovis_link_4">
        <visual>
            <geometry>
                <mesh filename="package://ovis_description/meshes/visual/ovis_forearm.stl" />
            </geometry>
            <origin rpy="0 0 0" xyz="0 0 0" />
        </visual>
        <collision>
            <geometry>
                <mesh filename="package://ovis_description/meshes/visual/ovis_forearm.stl" />
            </geometry>
            <origin rpy="0 0 0" xyz="0 0 0" />
        </collision>
        
<inertial>
            <mass value="0.652" />
            <origin rpy="0 0 0" xyz="0.00011113 0.12506366 0.00482529" />
            <inertia ixx="0.00685564" ixy="-4.5e-006" ixz="-4.1e-007" iyy="0.00052903" iyz="0.00038138" izz="0.00686163" />
        </inertial>

    </link>
    <joint name="arm_joint_4" type="continuous">
        <parent link="ovis_link_3" />
        <child link="ovis_link_4" />
        <axis xyz="0 1 0" />
        <limit effort="20" lower="-12.5663706144" upper="12.5663706144" velocity="0.837758040957" />
        <origin rpy="0 0 0" xyz="0.0889 0.047625 0" />
        <dynamics damping="0.0" friction="0.0" />
    </joint>
    <transmission name="arm_joint_4_trans">
        <type>transmission_interface/SimpleTransmission</type>
        <joint name="arm_joint_4">
            <hardwareInterface>hardware_interface/PositionJointInterface</hardwareInterface>
        </joint>
        <actuator name="arm_joint_4_actuator">
            <hardwareInterface>hardware_interface/PositionJointInterface</hardwareInterface>
            <mechanicalReduction>160</mechanicalReduction>
        </actuator>
    </transmission>
    <!--For torque sensing in simulation-->
    <gazebo reference="arm_joint_4">
        <provideFeedback>true</provideFeedback>
    </gazebo>
    <gazebo>
        <plugin filename="libgazebo_ros_ft_sensor.so" name="ft_sensor">
            <updateRate>30.0</updateRate>
            <topicName>arm_joint_4_ft_sensor_topic</topicName>
            <jointName>arm_joint_4</jointName>
        </plugin>
    </gazebo>
    <link name="ovis_link_5">
        <visual>
            <geometry>
                <mesh filename="package://ovis_description/meshes/visual/ovis_wrist.stl" />
            </geometry>
            <origin rpy="0 0 0" xyz="0 0 0" />
        </visual>
        <collision>
            <geometry>
                <mesh filename="package://ovis_description/meshes/visual/ovis_wrist.stl" />
            </geometry>
            <origin rpy="0 0 0" xyz="0 0 0" />
        </collision>
        
<inertial>
            <mass value="0.41555" />
            <origin rpy="0 0 0" xyz="0.0 0.03086454 -0.00810577" />
            <inertia ixx="0.00055858" ixy="-4.3e-007" ixz="-2.8e-007" iyy="0.00020049" iyz="9.39e-005" izz="0.00057545" />
        </inertial>

    </link>
    <joint name="arm_joint_5" type="revolute">
        <parent link="ovis_link_4" />
        <child link="ovis_link_5" />
        <axis xyz="0 0 1" />
        <limit effort="20" lower="-1.57079632679" upper="1.57079632679" velocity="0.837758040957" />
        <origin rpy="0 0 0" xyz="0 0.265 0" />
        <dynamics damping="0.0" friction="0.0" />
    </joint>
    <transmission name="arm_joint_5_trans">
        <type>transmission_interface/SimpleTransmission</type>
        <joint name="arm_joint_5">
            <hardwareInterface>hardware_interface/PositionJointInterface</hardwareInterface>
        </joint>
        <actuator name="arm_joint_5_actuator">
            <hardwareInterface>hardware_interface/PositionJointInterface</hardwareInterface>
            <mechanicalReduction>160</mechanicalReduction>
        </actuator>
    </transmission>
    <!--For torque sensing in simulation-->
    <gazebo reference="arm_joint_5">
        <provideFeedback>true</provideFeedback>
    </gazebo>
    <gazebo>
        <plugin filename="libgazebo_ros_ft_sensor.so" name="ft_sensor">
            <updateRate>30.0</updateRate>
            <topicName>arm_joint_5_ft_sensor_topic</topicName>
            <jointName>arm_joint_5</jointName>
        </plugin>
    </gazebo>
    <link name="ovis_link_6">
        <visual>
            <geometry>
                <mesh filename="package://ovis_description/meshes/visual/ovis_flange.stl" />
            </geometry>
            <origin rpy="0 0 0" xyz="0 0 0" />
        </visual>
        <collision>
            <geometry>
                <mesh filename="package://ovis_description/meshes/collision/ovis_flange.stl" />
            </geometry>
            <origin rpy="0 0 0" xyz="0 0 0" />
        </collision>
        
<inertial>
            <mass value="0.6448" />
            <origin rpy="0 0 0" xyz="-0.00120093 0.06932019 -0.00169931" />
            <inertia ixx="0.00326124" ixy="-1.39e-005" ixz="-1.38e-006" iyy="0.00125679" iyz="1.69e-005" izz="0.00393291" />
        </inertial>

    </link>
    <joint name="arm_joint_6" type="continuous">
        <parent link="ovis_link_5" />
        <child link="ovis_link_6" />
        <axis xyz="0 0 1" />
        <limit effort="20" lower="-6.28318530718" upper="6.28318530718" velocity="0.837758040957" />
        <origin rpy="1.57079632679 1.57079632679 0" xyz="0 0.0762 0" />
        <dynamics damping="0.0" friction="0.0" />
    </joint>
    <transmission name="arm_joint_6_trans">
        <type>transmission_interface/SimpleTransmission</type>
        <joint name="arm_joint_6">
            <hardwareInterface>hardware_interface/PositionJointInterface</hardwareInterface>
        </joint>
        <actuator name="arm_joint_6_actuator">
            <hardwareInterface>hardware_interface/PositionJointInterface</hardwareInterface>
            <mechanicalReduction>160</mechanicalReduction>
        </actuator>
    </transmission>
    <!--For torque sensing in simulation-->
    <gazebo reference="arm_joint_6">
        <provideFeedback>true</provideFeedback>
    </gazebo>
    <gazebo>
        <plugin filename="libgazebo_ros_ft_sensor.so" name="ft_sensor">
            <updateRate>30.0</updateRate>
            <topicName>arm_joint_6_ft_sensor_topic</topicName>
            <jointName>arm_joint_6</jointName>
        </plugin>
    </gazebo>
    <link name="ovis_link_tool0" />
    <joint name="ovis_joint_tool0" type="fixed">
        <parent link="ovis_link_6" />
        <child link="ovis_link_tool0" />
        <axis xyz="0 0 0" />
        <limit effort="2000" lower="0" upper="0" velocity="1" />
        <origin rpy="0 3.14159265359 1.57079632679" xyz="0 0 -0.09215" />
    </joint>
    <link name="ovis_end_effector" />
    <joint name="ovis_joint_end_effector" type="fixed">
        <parent link="ovis_link_tool0" />
        <child link="ovis_end_effector" />
        <axis xyz="0 0 0" />
        <limit effort="2000" lower="0" upper="0" velocity="1" />
        <origin rpy="0 0 0" xyz="0 0 0.1778" />
    </joint>
    <joint name="ovis_camera" type="fixed">
        <parent link="ovis_link_6" />
        <child link="ovis_camera" />
        <axis xyz="0 0 1" />
        <limit effort="2000" lower="0" upper="0" velocity="1" />
        <origin rpy="0 1.57079632679 1.57079632679" xyz="0 0.091842 -0.0732" />
    </joint>
    <link name="world" />
    <joint name="connect_root_and_world" type="fixed">
        <child link="ovis_root" />
        <parent link="world" />
        <origin rpy="0 0 0" xyz="0 0 0" />
    </joint>
    <!--
    <transmission name="trans_arm_joint_1">
        <type>transmission_interface/SimpleTransmission</type>
        <joint name="arm_joint_1">
            <hardwareInterface>hardware_interface/PositionJointInterface</hardwareInterface>
        </joint>
        <actuator name="arm_joint_1_motor">
            <hardwareInterface>hardware_interface/PositionJointInterface</hardwareInterface>
            <mechanicalReduction>1</mechanicalReduction>
        </actuator>
    </transmission>
    <transmission name="trans_arm_joint_2">
        <type>transmission_interface/SimpleTransmission</type>
        <joint name="arm_joint_2">
            <hardwareInterface>hardware_interface/PositionJointInterface</hardwareInterface>
        </joint>
        <actuator name="arm_joint_2_motor">
            <hardwareInterface>hardware_interface/PositionJointInterface</hardwareInterface>
            <mechanicalReduction>1</mechanicalReduction>
        </actuator>
    </transmission>
    <transmission name="trans_arm_joint_3">
        <type>transmission_interface/SimpleTransmission</type>
        <joint name="arm_joint_3">
            <hardwareInterface>hardware_interface/PositionJointInterface</hardwareInterface>
        </joint>
        <actuator name="arm_joint_3_motor">
            <hardwareInterface>hardware_interface/PositionJointInterface</hardwareInterface>
            <mechanicalReduction>1</mechanicalReduction>
        </actuator>
    </transmission>
    <transmission name="trans_arm_joint_4">
        <type>transmission_interface/SimpleTransmission</type>
        <joint name="arm_joint_4">
            <hardwareInterface>hardware_interface/PositionJointInterface</hardwareInterface>
        </joint>
        <actuator name="arm_joint_4_motor">
            <hardwareInterface>hardware_interface/PositionJointInterface</hardwareInterface>
            <mechanicalReduction>1</mechanicalReduction>
        </actuator>
    </transmission>
    <transmission name="trans_arm_joint_5">
        <type>transmission_interface/SimpleTransmission</type>
        <joint name="arm_joint_5">
            <hardwareInterface>hardware_interface/PositionJointInterface</hardwareInterface>
        </joint>
        <actuator name="arm_joint_5_motor">
            <hardwareInterface>hardware_interface/PositionJointInterface</hardwareInterface>
            <mechanicalReduction>1</mechanicalReduction>
        </actuator>
    </transmission>
    <transmission name="trans_arm_joint_6">
        <type>transmission_interface/SimpleTransmission</type>
        <joint name="arm_joint_6">
            <hardwareInterface>hardware_interface/PositionJointInterface</hardwareInterface>
        </joint>
        <actuator name="arm_joint_6_motor">
            <hardwareInterface>hardware_interface/PositionJointInterface</hardwareInterface>
            <mechanicalReduction>1</mechanicalReduction>
        </actuator>
    </transmission>
    -->
</robot>
